Workbook

Sheet Dataset
A1: Customer Id | B1: Gender | C1: Age | D1: Income | E1: Tenure | F1: Avg. Session Time | G1: Total Promo | H1: Bounce Rate | I1: Yearly Spending
A2: 100 | B2: M | C2: 30 | D2: 12000000 | E2: 10 | F2: 520 | G2: 12 | H2: 56 | I2: 4000000
A3: 101 | B3: F | C3: 30 | D3: 8600000 | E3: 7.3 | F3: 744 | G3: 9.46 | H3: 57 | I3: 4300000
A4: 102 | B4: M | C4: 30 | D4: 7200000 | E4: 2.8 | F4: 113.96667 | G4: 22 | H4: 40 | I4: 4800000
A5: 103 | B5: F | C5: 30 | D5: 30000000 | E5: 8.5 | F5: 168.75 | G5: 18 | H5: 37 | I5: 5500000
A6: 104 | B6: M | C6: 20 | D6: 10440000 | E6: 13.6 | F6: 736 | G6: 13.5 | H6: 36.2 | I6: 5800000
A7: 105 | B7: F | C7: 20 | D7: 18900000 | E7: 9.3 | F7: 1104 | G7: 8.8 | H7: 30.7 | I7: 6300000
A8: 106 | B8: M | C8: 20 | D8: 13200000 | E8: 4.6 | F8: 160.76667 | G8: 26.4 | H8: 31 | I8: 6600000
A9: 107 | B9: F | C9: 21.3 | D9: 10650000 | E9: 10.1 | F9: 211.95 | G9: 25.56 | H9: 21.9 | I9: 7100000
A10: 108 | B10: M | C10: 32.6 | D10: 10140000 | E10: 17.6 | F10: 976 | G10: 21 | H10: 15 | I10: 7800000
A11: 109 | B11: F | C11: 33.6 | D11: 14580000 | E11: 11.1 | F11: 1428 | G11: 16.5 | H11: 10.9 | I11: 8100000
A12: 110 | B12: M | C12: 35 | D12: 13200000 | E12: 6.6 | F12: 212.76667 | G12: 34.4 | H12: 5 | I12: 8600000
A13: 111 | B13: F | C13: 36 | D13: 10650000 | E13: 12.3 | F13: 271.35 | G13: 33.48 | H13: 25 | I13: 9300000
... A300: 398 | B300: M | C300: 27 | D300: 6500000 | E300: 11 | F300: 330 | G300: 12 | H300: 45 | I300: 5000000

Sheet 1. Correlation
A2: Pearson Correlation (CORREL) atas 299 baris data TokoBli.
A4: Keterangan Variabel
B5: X1 | C5: X2 | D5: X3 | E5: X4 | F5: X5 | G5: X6 | H5: Y
A6: Nama | B6: Age | C6: Income | D6: Tenure | E6: Avg. Session Time | F6: Total Promo | G6: Bounce Rate | H6: Yearly Spending
A8: Correlation Matrix
B9: X1 | C9: X2 | D9: X3 | E9: X4 | F9: X5 | G9: X6 | H9: Y
A10: X1 Age | B10: =CORREL(Dataset!$C$2:$C$300,Dataset!$C$2:$C$300) -> 1 | C10: =CORREL(Dataset!$C$2:$C$300,Dataset!$D$2:$D$300) -> 0.14077443 | D10: =CORREL(Dataset!$C$2:$C$300,Dataset!$E$2:$E$300) -> 0.16034759 | E10: =CORREL(Dataset!$C$2:$C$300,Dataset!$F$2:$F$300) -> 0.19344527 | F10: =CORREL(Dataset!$C$2:$C$300,Dataset!$G$2:$G$300) -> 0.20780328 | G10: =CORREL(Dataset!$C$2:$C$300,Dataset!$H$2:$H$300) -> -0.12897538 | H10: =CORREL(Dataset!$C$2:$C$300,Dataset!$I$2:$I$300) -> 0.22134233
A11: X2 Income | B11: =CORREL(Dataset!$D$2:$D$300,Dataset!$C$2:$C$300) -> 0.14077443 | C11: =CORREL(Dataset!$D$2:$D$300,Dataset!$D$2:$D$300) -> 1 | D11: =CORREL(Dataset!$D$2:$D$300,Dataset!$E$2:$E$300) -> 0.37894671 | E11: =CORREL(Dataset!$D$2:$D$300,Dataset!$F$2:$F$300) -> 0.48369206 | F11: =CORREL(Dataset!$D$2:$D$300,Dataset!$G$2:$G$300) -> 0.44567271 | G11: =CORREL(Dataset!$D$2:$D$300,Dataset!$H$2:$H$300) -> -0.4483756 | H11: =CORREL(Dataset!$D$2:$D$300,Dataset!$I$2:$I$300) -> 0.5274775
A12: X3 Tenure | B12: =CORREL(Dataset!$E$2:$E$300,Dataset!$C$2:$C$300) -> 0.16034759 | C12: =CORREL(Dataset!$E$2:$E$300,Dataset!$D$2:$D$300) -> 0.37894671 | D12: =CORREL(Dataset!$E$2:$E$300,Dataset!$E$2:$E$300) -> 1 | E12: =CORREL(Dataset!$E$2:$E$300,Dataset!$F$2:$F$300) -> 0.68533196 | F12: =CORREL(Dataset!$E$2:$E$300,Dataset!$G$2:$G$300) -> 0.62137447 | G12: =CORREL(Dataset!$E$2:$E$300,Dataset!$H$2:$H$300) -> -0.57027661 | H12: =CORREL(Dataset!$E$2:$E$300,Dataset!$I$2:$I$300) -> 0.71450637
A13: X4 Avg. Session Time | B13: =CORREL(Dataset!$F$2:$F$300,Dataset!$C$2:$C$300) -> 0.19344527 | C13: =CORREL(Dataset!$F$2:$F$300,Dataset!$D$2:$D$300) -> 0.48369206 | D13: =CORREL(Dataset!$F$2:$F$300,Dataset!$E$2:$E$300) -> 0.68533196 | E13: =CORREL(Dataset!$F$2:$F$300,Dataset!$F$2:$F$300) -> 1 | F13: =CORREL(Dataset!$F$2:$F$300,Dataset!$G$2:$G$300) -> 0.77688616 | G13: =CORREL(Dataset!$F$2:$F$300,Dataset!$H$2:$H$300) -> -0.78730561 | H13: =CORREL(Dataset!$F$2:$F$300,Dataset!$I$2:$I$300) -> 0.91408271
A14: X5 Total Promo | B14: =CORREL(Dataset!$G$2:$G$300,Dataset!$C$2:$C$300) -> 0.20780328 | C14: =CORREL(Dataset!$G$2:$G$300,Dataset!$D$2:$D$300) -> 0.44567271 | D14: =CORREL(Dataset!$G$2:$G$300,Dataset!$E$2:$E$300) -> 0.62137447 | E14: =CORREL(Dataset!$G$2:$G$300,Dataset!$F$2:$F$300) -> 0.77688616 | F14: =CORREL(Dataset!$G$2:$G$300,Dataset!$G$2:$G$300) -> 1 | G14: =CORREL(Dataset!$G$2:$G$300,Dataset!$H$2:$H$300) -> -0.79414346 | H14: =CORREL(Dataset!$G$2:$G$300,Dataset!$I$2:$I$300) -> 0.87666951
A15: X6 Bounce Rate | B15: =CORREL(Dataset!$H$2:$H$300,Dataset!$C$2:$C$300) -> -0.12897538 | C15: =CORREL(Dataset!$H$2:$H$300,Dataset!$D$2:$D$300) -> -0.4483756 | D15: =CORREL(Dataset!$H$2:$H$300,Dataset!$E$2:$E$300) -> -0.57027661 | E15: =CORREL(Dataset!$H$2:$H$300,Dataset!$F$2:$F$300) -> -0.78730561 | F15: =CORREL(Dataset!$H$2:$H$300,Dataset!$G$2:$G$300) -> -0.79414346 | G15: =CORREL(Dataset!$H$2:$H$300,Dataset!$H$2:$H$300) -> 1 | H15: =CORREL(Dataset!$H$2:$H$300,Dataset!$I$2:$I$300) -> -0.86252427
A16: Y Yearly Spending | B16: =CORREL(Dataset!$I$2:$I$300,Dataset!$C$2:$C$300) -> 0.22134233 | C16: =CORREL(Dataset!$I$2:$I$300,Dataset!$D$2:$D$300) -> 0.5274775 | D16: =CORREL(Dataset!$I$2:$I$300,Dataset!$E$2:$E$300) -> 0.71450637 | E16: =CORREL(Dataset!$I$2:$I$300,Dataset!$F$2:$F$300) -> 0.91408271 | F16: =CORREL(Dataset!$I$2:$I$300,Dataset!$G$2:$G$300) -> 0.87666951 | G16: =CORREL(Dataset!$I$2:$I$300,Dataset!$H$2:$H$300) -> -0.86252427 | H16: =CORREL(Dataset!$I$2:$I$300,Dataset!$I$2:$I$300) -> 1
A19: Korelasi Terhadap Yearly Spending (Y)
A20: Variabel | B20: r | C20: Kekuatan | D20: Arah
A21: X1 Age | B21: =CORREL(Dataset!$C$2:$C$300,Dataset!$I$2:$I$300) -> 0.22134233 | C21: =IF(ABS(B21)>=0.7,"Kuat",IF(ABS(B21)>=0.4,"Sedang",IF(ABS(B21)>=0.2,"Lemah","Sangat Lemah"))) -> Lemah | D21: =IF(B21>0,"Positif","Negatif") -> Positif
A22: X2 Income | B22: =CORREL(Dataset!$D$2:$D$300,Dataset!$I$2:$I$300) -> 0.5274775 | C22: =IF(ABS(B22)>=0.7,"Kuat",IF(ABS(B22)>=0.4,"Sedang",IF(ABS(B22)>=0.2,"Lemah","Sangat Lemah"))) -> Sedang | D22: =IF(B22>0,"Positif","Negatif") -> Positif
A23: X3 Tenure | B23: =CORREL(Dataset!$E$2:$E$300,Dataset!$I$2:$I$300) -> 0.71450637 | C23: =IF(ABS(B23)>=0.7,"Kuat",IF(ABS(B23)>=0.4,"Sedang",IF(ABS(B23)>=0.2,"Lemah","Sangat Lemah"))) -> Kuat | D23: =IF(B23>0,"Positif","Negatif") -> Positif
A24: X4 Avg. Session Time | B24: =CORREL(Dataset!$F$2:$F$300,Dataset!$I$2:$I$300) -> 0.91408271 | C24: =IF(ABS(B24)>=0.7,"Kuat",IF(ABS(B24)>=0.4,"Sedang",IF(ABS(B24)>=0.2,"Lemah","Sangat Lemah"))) -> Kuat | D24: =IF(B24>0,"Positif","Negatif") -> Positif
A25: X5 Total Promo | B25: =CORREL(Dataset!$G$2:$G$300,Dataset!$I$2:$I$300) -> 0.87666951 | C25: =IF(ABS(B25)>=0.7,"Kuat",IF(ABS(B25)>=0.4,"Sedang",IF(ABS(B25)>=0.2,"Lemah","Sangat Lemah"))) -> Kuat | D25: =IF(B25>0,"Positif","Negatif") -> Positif
A26: X6 Bounce Rate | B26: =CORREL(Dataset!$H$2:$H$300,Dataset!$I$2:$I$300) -> -0.86252427 | C26: =IF(ABS(B26)>=0.7,"Kuat",IF(ABS(B26)>=0.4,"Sedang",IF(ABS(B26)>=0.2,"Lemah","Sangat Lemah"))) -> Kuat | D26: =IF(B26>0,"Positif","Negatif") -> Negatif
A28: Insight Korelasi
A29: X4 Avg. Session Time paling kuat berhubungan positif dengan Y (r = 0,914). Makin lama sesi, makin besar belanja tahunan.
A30: X5 Total Promo kuat positif (r = 0,877) dan X3 Tenure kuat positif (r = 0,715).
A31: X6 Bounce Rate kuat negatif (r = -0,863). Makin tinggi bounce, makin kecil belanja tahunan.
A32: X2 Income sedang positif (r = 0,527) dan X1 Age paling lemah (r = 0,221).
A33: Antar variabel independen terdapat korelasi cukup tinggi (X4 dengan X5 = 0,777 dan X4 dengan X6 = -0,787) sehingga multikolinearitas perlu diuji di tahap regresi.
A34: Eskalasi ke regresi: korelasi hanya mengukur keeratan hubungan, bukan besar pengaruh, sehingga analisis dilanjutkan ke regresi berganda pada sheet 2.

Sheet 2. Iterasi Model
A1: CASE 2 - Regresi Linear Berganda dengan Stepwise Regression (Backward Elimination)
A2: Y = b0 + b1*x1 + b2*x2 + b3*x3 + b4*x4 + b5*x5 + b6*x6
A3: Alpha = 0,05. H0 berarti variabel tidak berpengaruh signifikan terhadap Y, H1 berarti berpengaruh signifikan.
A5: Keterangan Variabel
B6: X1 | C6: X2 | D6: X3 | E6: X4 | F6: X5 | G6: X6 | H6: Y
A7: Nama | B7: Age | C7: Income | D7: Tenure | E7: Avg. Session Time | F7: Total Promo | G7: Bounce Rate | H7: Yearly Spending
A9: Iterasi 1
B10: Coefficients | C10: Standard Error | D10: t-Stat | E10: P-value | F10: Keputusan | G10: Kesimpulan | J10: Goodness of Fit | K10: Nilai | M10: df residual
A11: Intercept | B11: {=INDEX(LINEST(Dataset!$I$2:$I$300,Dataset!$C$2:$H$300,TRUE(),TRUE()),1,7)} -> 1947879.7 | C11: {=INDEX(LINEST(Dataset!$I$2:$I$300,Dataset!$C$2:$H$300,TRUE(),TRUE()),2,7)} -> 594065.05 | D11: =B11/C11 -> 3.2788997 | E11: =TDIST(ABS(D11),$M$11,2) -> 0.0011681982 | F11: =IF(E11<0.05,"H1 diterima","H0 diterima") -> H1 diterima | G11: =IF(E11<0.05,"Signifikan","Tidak Signifikan") -> Signifikan | J11: R Square | K11: {=INDEX(LINEST(Dataset!$I$2:$I$300,Dataset!$C$2:$H$300,TRUE(),TRUE()),3,1)} -> 0.92927811 | M11: {=INDEX(LINEST(Dataset!$I$2:$I$300,Dataset!$C$2:$H$300,TRUE(),TRUE()),4,2)} -> 292
A12: X1 Age | B12: {=INDEX(LINEST(Dataset!$I$2:$I$300,Dataset!$C$2:$H$300,TRUE(),TRUE()),1,6)} -> 30555.492 | C12: {=INDEX(LINEST(Dataset!$I$2:$I$300,Dataset!$C$2:$H$300,TRUE(),TRUE()),2,6)} -> 16729.072 | D12: =B12/C12 -> 1.8264905 | E12: =TDIST(ABS(D12),$M$11,2) -> 0.068797312 | F12: =IF(E12<0.05,"H1 diterima","H0 diterima") -> H0 diterima | G12: =IF(E12<0.05,"Signifikan","Tidak Signifikan") -> Tidak Signifikan | H12: =IF(AND(E12=MAX($E$12:$E$17),E12>0.05),"P-value paling besar, variabel ini dikeluarkan","") -> P-value paling besar, variabel ini dikeluarkan | J12: Adjusted R Square | K12: =1-(1-K11)*(299-1)/(299-6-1) -> 0.92782492
A13: X2 Income | B13: {=INDEX(LINEST(Dataset!$I$2:$I$300,Dataset!$C$2:$H$300,TRUE(),TRUE()),1,5)} -> 0.035824641 | C13: {=INDEX(LINEST(Dataset!$I$2:$I$300,Dataset!$C$2:$H$300,TRUE(),TRUE()),2,5)} -> 0.011117301 | D13: =B13/C13 -> 3.2224224 | E13: =TDIST(ABS(D13),$M$11,2) -> 0.0014149349 | F13: =IF(E13<0.05,"H1 diterima","H0 diterima") -> H1 diterima | G13: =IF(E13<0.05,"Signifikan","Tidak Signifikan") -> Signifikan | H13: =IF(AND(E13=MAX($E$12:$E$17),E13>0.05),"P-value paling besar, variabel ini dikeluarkan","") | J13: Standard Error | K13: {=INDEX(LINEST(Dataset!$I$2:$I$300,Dataset!$C$2:$H$300,TRUE(),TRUE()),3,2)} -> 1384406.1
A14: X3 Tenure | B14: {=INDEX(LINEST(Dataset!$I$2:$I$300,Dataset!$C$2:$H$300,TRUE(),TRUE()),1,4)} -> 64158.047 | C14: {=INDEX(LINEST(Dataset!$I$2:$I$300,Dataset!$C$2:$H$300,TRUE(),TRUE()),2,4)} -> 14092.067 | D14: =B14/C14 -> 4.5527777 | E14: =TDIST(ABS(D14),$M$11,2) -> 7.780364e-06 | F14: =IF(E14<0.05,"H1 diterima","H0 diterima") -> H1 diterima | G14: =IF(E14<0.05,"Signifikan","Tidak Signifikan") -> Signifikan | H14: =IF(AND(E14=MAX($E$12:$E$17),E14>0.05),"P-value paling besar, variabel ini dikeluarkan","") | J14: F-Statistic | K14: {=INDEX(LINEST(Dataset!$I$2:$I$300,Dataset!$C$2:$H$300,TRUE(),TRUE()),4,1)} -> 639.47478
A15: X4 Avg. Session Time | B15: {=INDEX(LINEST(Dataset!$I$2:$I$300,Dataset!$C$2:$H$300,TRUE(),TRUE()),1,3)} -> 6286.9828 | C15: {=INDEX(LINEST(Dataset!$I$2:$I$300,Dataset!$C$2:$H$300,TRUE(),TRUE()),2,3)} -> 456.26844 | D15: =B15/C15 -> 13.779131 | E15: =TDIST(ABS(D15),$M$11,2) -> 0 | F15: =IF(E15<0.05,"H1 diterima","H0 diterima") -> H1 diterima | G15: =IF(E15<0.05,"Signifikan","Tidak Signifikan") -> Signifikan | H15: =IF(AND(E15=MAX($E$12:$E$17),E15>0.05),"P-value paling besar, variabel ini dikeluarkan","") | J15: Significance F | K15: =FDIST(K14,6,$M$11) -> 0
A16: X5 Total Promo | B16: {=INDEX(LINEST(Dataset!$I$2:$I$300,Dataset!$C$2:$H$300,TRUE(),TRUE()),1,2)} -> 133215.7 | C16: {=INDEX(LINEST(Dataset!$I$2:$I$300,Dataset!$C$2:$H$300,TRUE(),TRUE()),2,2)} -> 13692.773 | D16: =B16/C16 -> 9.7289058 | E16: =TDIST(ABS(D16),$M$11,2) -> 0 | F16: =IF(E16<0.05,"H1 diterima","H0 diterima") -> H1 diterima | G16: =IF(E16<0.05,"Signifikan","Tidak Signifikan") -> Signifikan | H16: =IF(AND(E16=MAX($E$12:$E$17),E16>0.05),"P-value paling besar, variabel ini dikeluarkan","") | J16: Observasi | K16: =299 -> 299
A17: X6 Bounce Rate | B17: {=INDEX(LINEST(Dataset!$I$2:$I$300,Dataset!$C$2:$H$300,TRUE(),TRUE()),1,1)} -> -50349.938 | C17: {=INDEX(LINEST(Dataset!$I$2:$I$300,Dataset!$C$2:$H$300,TRUE(),TRUE()),2,1)} -> 6451.8134 | D17: =B17/C17 -> -7.803998 | E17: =TDIST(ABS(D17),$M$11,2) -> 0 | F17: =IF(E17<0.05,"H1 diterima","H0 diterima") -> H1 diterima | G17: =IF(E17<0.05,"Signifikan","Tidak Signifikan") -> Signifikan | H17: =IF(AND(E17=MAX($E$12:$E$17),E17>0.05),"P-value paling besar, variabel ini dikeluarkan","") | J17: Jumlah X | K17: =6 -> 6
A19: Hasil Iterasi 1: X1 Age punya P-value terbesar yaitu 0,0688 dan berada di atas 0,05, sehingga X1 dikeluarkan lalu model dihitung ulang pada Iterasi 2.
A21: Iterasi 2
B22: Coefficients | C22: Standard Error | D22: t-Stat | E22: P-value | F22: Keputusan | G22: Kesimpulan | J22: Goodness of Fit | K22: Nilai | M22: df residual
A23: Intercept | B23: {=INDEX(LINEST(Dataset!$I$2:$I$300,Dataset!$D$2:$H$300,TRUE(),TRUE()),1,6)} -> 2590241.5 | C23: {=INDEX(LINEST(Dataset!$I$2:$I$300,Dataset!$D$2:$H$300,TRUE(),TRUE()),2,6)} -> 480680.5 | D23: =B23/C23 -> 5.3886968 | E23: =TDIST(ABS(D23),$M$23,2) -> 1.460639e-07 | F23: =IF(E23<0.05,"H1 diterima","H0 diterima") -> H1 diterima | G23: =IF(E23<0.05,"Signifikan","Tidak Signifikan") -> Signifikan | J23: R Square | K23: {=INDEX(LINEST(Dataset!$I$2:$I$300,Dataset!$D$2:$H$300,TRUE(),TRUE()),3,1)} -> 0.92847012 | M23: {=INDEX(LINEST(Dataset!$I$2:$I$300,Dataset!$D$2:$H$300,TRUE(),TRUE()),4,2)} -> 293
A24: X2 Income | B24: {=INDEX(LINEST(Dataset!$I$2:$I$300,Dataset!$D$2:$H$300,TRUE(),TRUE()),1,5)} -> 0.036843174 | C24: {=INDEX(LINEST(Dataset!$I$2:$I$300,Dataset!$D$2:$H$300,TRUE(),TRUE()),2,5)} -> 0.011147482 | D24: =B24/C24 -> 3.305067 | E24: =TDIST(ABS(D24),$M$23,2) -> 0.001067575 | F24: =IF(E24<0.05,"H1 diterima","H0 diterima") -> H1 diterima | G24: =IF(E24<0.05,"Signifikan","Tidak Signifikan") -> Signifikan | H24: =IF(AND(E24=MAX($E$24:$E$28),E24>0.05),"P-value paling besar, variabel ini dikeluarkan","") | J24: Adjusted R Square | K24: =1-(1-K23)*(299-1)/(299-5-1) -> 0.92724947
A25: X3 Tenure | B25: {=INDEX(LINEST(Dataset!$I$2:$I$300,Dataset!$D$2:$H$300,TRUE(),TRUE()),1,4)} -> 64576.213 | C25: {=INDEX(LINEST(Dataset!$I$2:$I$300,Dataset!$D$2:$H$300,TRUE(),TRUE()),2,4)} -> 14146.265 | D25: =B25/C25 -> 4.5648948 | E25: =TDIST(ABS(D25),$M$23,2) -> 7.3631818e-06 | F25: =IF(E25<0.05,"H1 diterima","H0 diterima") -> H1 diterima | G25: =IF(E25<0.05,"Signifikan","Tidak Signifikan") -> Signifikan | H25: =IF(AND(E25=MAX($E$24:$E$28),E25>0.05),"P-value paling besar, variabel ini dikeluarkan","") | J25: Standard Error | K25: {=INDEX(LINEST(Dataset!$I$2:$I$300,Dataset!$D$2:$H$300,TRUE(),TRUE()),3,2)} -> 1389914
A26: X4 Avg. Session Time | B26: {=INDEX(LINEST(Dataset!$I$2:$I$300,Dataset!$D$2:$H$300,TRUE(),TRUE()),1,3)} -> 6341.9017 | C26: {=INDEX(LINEST(Dataset!$I$2:$I$300,Dataset!$D$2:$H$300,TRUE(),TRUE()),2,3)} -> 457.08797 | D26: =B26/C26 -> 13.874576 | E26: =TDIST(ABS(D26),$M$23,2) -> 0 | F26: =IF(E26<0.05,"H1 diterima","H0 diterima") -> H1 diterima | G26: =IF(E26<0.05,"Signifikan","Tidak Signifikan") -> Signifikan | H26: =IF(AND(E26=MAX($E$24:$E$28),E26>0.05),"P-value paling besar, variabel ini dikeluarkan","") | J26: F-Statistic | K26: {=INDEX(LINEST(Dataset!$I$2:$I$300,Dataset!$D$2:$H$300,TRUE(),TRUE()),4,1)} -> 760.63801
A27: X5 Total Promo | B27: {=INDEX(LINEST(Dataset!$I$2:$I$300,Dataset!$D$2:$H$300,TRUE(),TRUE()),1,2)} -> 136147.72 | C27: {=INDEX(LINEST(Dataset!$I$2:$I$300,Dataset!$D$2:$H$300,TRUE(),TRUE()),2,2)} -> 13652.451 | D27: =B27/C27 -> 9.9724015 | E27: =TDIST(ABS(D27),$M$23,2) -> 0 | F27: =IF(E27<0.05,"H1 diterima","H0 diterima") -> H1 diterima | G27: =IF(E27<0.05,"Signifikan","Tidak Signifikan") -> Signifikan | H27: =IF(AND(E27=MAX($E$24:$E$28),E27>0.05),"P-value paling besar, variabel ini dikeluarkan","") | J27: Significance F | K27: =FDIST(K26,5,$M$23) -> 0
A28: X6 Bounce Rate | B28: {=INDEX(LINEST(Dataset!$I$2:$I$300,Dataset!$D$2:$H$300,TRUE(),TRUE()),1,1)} -> -49209.126 | C28: {=INDEX(LINEST(Dataset!$I$2:$I$300,Dataset!$D$2:$H$300,TRUE(),TRUE()),2,1)} -> 6447.0575 | D28: =B28/C28 -> -7.632804 | E28: =TDIST(ABS(D28),$M$23,2) -> 0 | F28: =IF(E28<0.05,"H1 diterima","H0 diterima") -> H1 diterima | G28: =IF(E28<0.05,"Signifikan","Tidak Signifikan") -> Signifikan | H28: =IF(AND(E28=MAX($E$24:$E$28),E28>0.05),"P-value paling besar, variabel ini dikeluarkan","") | J28: Observasi | K28: =299 -> 299
J29: Jumlah X | K29: =5 -> 5
A30: Hasil Iterasi 2: seluruh variabel memiliki P-value di bawah 0,05 sehingga eliminasi berhenti. Total 2 iterasi dengan 1 kali eliminasi variabel.
A32: Uji Multikolinearitas (variabel yang lolos Iterasi 2)
A33: Correlation antar variabel independen. Batas: r lebih dari 0,8 atau kurang dari -0,8 berarti bermasalah.
A34: Correlation | B34: X2 | C34: X3 | D34: X4 | E34: X5 | F34: X6
A35: X2 Income | B35: =CORREL(Dataset!$D$2:$D$300,Dataset!$D$2:$D$300) -> 1 | C35: =CORREL(Dataset!$D$2:$D$300,Dataset!$E$2:$E$300) -> 0.37894671 | D35: =CORREL(Dataset!$D$2:$D$300,Dataset!$F$2:$F$300) -> 0.48369206 | E35: =CORREL(Dataset!$D$2:$D$300,Dataset!$G$2:$G$300) -> 0.44567271 | F35: =CORREL(Dataset!$D$2:$D$300,Dataset!$H$2:$H$300) -> -0.4483756
A36: X3 Tenure | B36: =CORREL(Dataset!$E$2:$E$300,Dataset!$D$2:$D$300) -> 0.37894671 | C36: =CORREL(Dataset!$E$2:$E$300,Dataset!$E$2:$E$300) -> 1 | D36: =CORREL(Dataset!$E$2:$E$300,Dataset!$F$2:$F$300) -> 0.68533196 | E36: =CORREL(Dataset!$E$2:$E$300,Dataset!$G$2:$G$300) -> 0.62137447 | F36: =CORREL(Dataset!$E$2:$E$300,Dataset!$H$2:$H$300) -> -0.57027661
A37: X4 Avg. Session Time | B37: =CORREL(Dataset!$F$2:$F$300,Dataset!$D$2:$D$300) -> 0.48369206 | C37: =CORREL(Dataset!$F$2:$F$300,Dataset!$E$2:$E$300) -> 0.68533196 | D37: =CORREL(Dataset!$F$2:$F$300,Dataset!$F$2:$F$300) -> 1 | E37: =CORREL(Dataset!$F$2:$F$300,Dataset!$G$2:$G$300) -> 0.77688616 | F37: =CORREL(Dataset!$F$2:$F$300,Dataset!$H$2:$H$300) -> -0.78730561
A38: X5 Total Promo | B38: =CORREL(Dataset!$G$2:$G$300,Dataset!$D$2:$D$300) -> 0.44567271 | C38: =CORREL(Dataset!$G$2:$G$300,Dataset!$E$2:$E$300) -> 0.62137447 | D38: =CORREL(Dataset!$G$2:$G$300,Dataset!$F$2:$F$300) -> 0.77688616 | E38: =CORREL(Dataset!$G$2:$G$300,Dataset!$G$2:$G$300) -> 1 | F38: =CORREL(Dataset!$G$2:$G$300,Dataset!$H$2:$H$300) -> -0.79414346
A39: X6 Bounce Rate | B39: =CORREL(Dataset!$H$2:$H$300,Dataset!$D$2:$D$300) -> -0.4483756 | C39: =CORREL(Dataset!$H$2:$H$300,Dataset!$E$2:$E$300) -> -0.57027661 | D39: =CORREL(Dataset!$H$2:$H$300,Dataset!$F$2:$F$300) -> -0.78730561 | E39: =CORREL(Dataset!$H$2:$H$300,Dataset!$G$2:$G$300) -> -0.79414346 | F39: =CORREL(Dataset!$H$2:$H$300,Dataset!$H$2:$H$300) -> 1
A41: Korelasi tertinggi antar variabel independen adalah -0,794 (X5 dengan X6), masih di bawah batas 0,8.
A43: Variance Inflation Factor (VIF). Batas: VIF lebih dari 5 berarti bermasalah.
A44: Variabel | B44: VIF | C44: Keterangan
A45: X2 Income | B45: {=INDEX(MINVERSE($B$35:$F$39),1,1)} -> 1.3380525 | C45: =IF(B45>5,"Ada multikolinearitas","Aman") -> Aman
A46: X3 Tenure | B46: {=INDEX(MINVERSE($B$35:$F$39),2,2)} -> 1.9663505 | C46: =IF(B46>5,"Ada multikolinearitas","Aman") -> Aman
A47: X4 Avg. Session Time | B47: {=INDEX(MINVERSE($B$35:$F$39),3,3)} -> 3.7794708 | C47: =IF(B47>5,"Ada multikolinearitas","Aman") -> Aman
...

Sheet 3. Prediction
A1: CASE 3 - Prediksi Potential Yearly Spending Customer Baru
A2: Sel kuning adalah input. Koefisien ditarik otomatis dari model final pada sheet 2. Iterasi Model.
A4: Variabel | B4: Nilai Customer Baru | C4: Koefisien Model Final | D4: Kontribusi
A5: X1 Age | B5: 20 | C5: tidak dipakai (tidak signifikan) | D5: 0
A6: X2 Income | B6: 20000000 | C6: ='2. Iterasi Model'!B24 -> 0.036843174 | D6: =B6*C6 -> 736863.48
A7: X3 Tenure | B7: 1 | C7: ='2. Iterasi Model'!B25 -> 64576.213 | D7: =B7*C7 -> 64576.213
A8: X4 Avg. Session Time | B8: 1000 | C8: ='2. Iterasi Model'!B26 -> 6341.9017 | D8: =B8*C8 -> 6341901.7
A9: X5 Total Promo | B9: 20 | C9: ='2. Iterasi Model'!B27 -> 136147.72 | D9: =B9*C9 -> 2722954.5
A10: X6 Bounce Rate | B10: 30 | C10: ='2. Iterasi Model'!B28 -> -49209.126 | D10: =B10*C10 -> -1476273.8
A11: b0 Intercept | C11: ='2. Iterasi Model'!B23 -> 2590241.5 | D11: =C11 -> 2590241.5
A13: Prediksi Yearly Spending | D13: =SUM(D5:D11) -> 10980264
A15: Rata-rata Yearly Spending seluruh customer | D15: =AVERAGE(Dataset!$I$2:$I$300) -> 9700334.4
A16: Selisih terhadap rata-rata | D16: =D13-D15 -> 1279929.1
A18: Input diambil dari soal nomor 3: Age 20, Income 20.000.000, Tenure 1, Avg. Session Time 1000, Total Promo 20, Bounce Rate 30.
A19: X1 Age tetap ditampilkan agar lengkap, tetapi tidak ikut dihitung karena tidak signifikan pada model final.
A20: Hasil: potensi belanja tahunan sekitar Rp10,98 juta, berada di atas rata-rata seluruh customer.

Sheet 4. Insight & Recommendation
A1: CASE 4 - Insight dan Rekomendasi
A3: Temuan Utama
A4: 1 | B4: X4 Avg. Session Time adalah pendorong terkuat belanja tahunan (r = 0,914 dan signifikan di regresi).
A5: 2 | B5: X5 Total Promo berdampak besar. Satu tambahan promo menaikkan belanja tahunan sekitar Rp136.148.
A6: 3 | B6: X6 Bounce Rate berdampak negatif. Kenaikan 1 poin menurunkan belanja tahunan sekitar Rp49.209.
A7: 4 | B7: X3 Tenure signifikan positif, sehingga retensi customer punya nilai ekonomi langsung.
A8: 5 | B8: X2 Income signifikan tetapi efeknya kecil, dan X1 Age tidak signifikan sehingga segmentasi umur tidak efektif.
A10: Rekomendasi
A11: 1 | B11: Perpanjang durasi sesi lewat personalisasi rekomendasi produk dan pencarian yang lebih relevan. Jadikan Avg. Session Time sebagai KPI utama tim produk.
A12: 2 | B12: Perbanyak dan pertajam promo seperti bundling dan voucher bertingkat karena dampaknya per unit paling besar.
A13: 3 | B13: Turunkan Bounce Rate dengan mempercepat loading, memperbaiki landing page, dan menyederhanakan alur checkout.
A14: 4 | B14: Bangun program loyalitas berbasis tenure dengan benefit bertingkat per tahun keanggotaan.
A15: 5 | B15: Alokasikan anggaran campaign ke perilaku (sesi, promo, bounce) bukan ke demografi umur.
A16: 6 | B16: Gunakan model final untuk scoring customer baru seperti pada Case 3 agar tim bisa memprioritaskan customer berpotensi tinggi sejak awal.
A18: Catatan Model | B18: Model final memakai 5 variabel dengan Adjusted R Square 0,927 dan lolos uji multikolinearitas. Hasil regresi menunjukkan hubungan, bukan sebab akibat mutlak.
